[2024-10-09T10:17:25.471+0000] {local_task_job_runner.py:120} INFO - ::group::Pre task execution logs
[2024-10-09T10:17:25.501+0000] {taskinstance.py:2076} INFO - Dependencies all met for dep_context=non-requeueable deps ti=<TaskInstance: dag_ETL_JsonData.check_folder manual__2024-10-09T10:07:22.471106+00:00 [queued]>
[2024-10-09T10:17:25.512+0000] {taskinstance.py:2076} INFO - Dependencies all met for dep_context=requeueable deps ti=<TaskInstance: dag_ETL_JsonData.check_folder manual__2024-10-09T10:07:22.471106+00:00 [queued]>
[2024-10-09T10:17:25.513+0000] {taskinstance.py:2306} INFO - Starting attempt 3 of 6
[2024-10-09T10:17:25.529+0000] {taskinstance.py:2330} INFO - Executing <Task(PythonOperator): check_folder> on 2024-10-09 10:07:22.471106+00:00
[2024-10-09T10:17:25.536+0000] {standard_task_runner.py:90} INFO - Running: ['***', 'tasks', 'run', 'dag_ETL_JsonData', 'check_folder', 'manual__2024-10-09T10:07:22.471106+00:00', '--job-id', '808', '--raw', '--subdir', 'DAGS_FOLDER/ETLProject/main.py', '--cfg-path', '/tmp/tmpkomzs3cr']
[2024-10-09T10:17:25.538+0000] {logging_mixin.py:188} WARNING - /home/***/.local/lib/python3.12/site-packages/***/task/task_runner/standard_task_runner.py:61 DeprecationWarning: This process (pid=856) is multi-threaded, use of fork() may lead to deadlocks in the child.
[2024-10-09T10:17:25.538+0000] {standard_task_runner.py:91} INFO - Job 808: Subtask check_folder
[2024-10-09T10:17:25.539+0000] {standard_task_runner.py:63} INFO - Started process 858 to run task
[2024-10-09T10:17:25.589+0000] {task_command.py:426} INFO - Running <TaskInstance: dag_ETL_JsonData.check_folder manual__2024-10-09T10:07:22.471106+00:00 [running]> on host ecb02e117702
[2024-10-09T10:17:25.689+0000] {taskinstance.py:2648} INFO - Exporting env vars: AIRFLOW_CTX_DAG_OWNER='admin' AIRFLOW_CTX_DAG_ID='dag_ETL_JsonData' AIRFLOW_CTX_TASK_ID='check_folder' AIRFLOW_CTX_EXECUTION_DATE='2024-10-09T10:07:22.471106+00:00' AIRFLOW_CTX_TRY_NUMBER='3' AIRFLOW_CTX_DAG_RUN_ID='manual__2024-10-09T10:07:22.471106+00:00'
[2024-10-09T10:17:25.690+0000] {taskinstance.py:430} INFO - ::endgroup::
[2024-10-09T10:17:25.721+0000] {taskinstance.py:441} INFO - ::group::Post task execution logs
[2024-10-09T10:17:25.722+0000] {taskinstance.py:2905} ERROR - Task failed with exception
Traceback (most recent call last):
  File "/home/airflow/.local/lib/python3.12/site-packages/airflow/models/taskinstance.py", line 465, in _execute_task
    result = _execute_callable(context=context, **execute_callable_kwargs)
             ^^^^^^^^^^^^^^^^^^^^^^^^^^^^^^^^^^^^^^^^^^^^^^^^^^^^^^^^^^^^^
  File "/home/airflow/.local/lib/python3.12/site-packages/airflow/models/taskinstance.py", line 432, in _execute_callable
    return execute_callable(context=context, **execute_callable_kwargs)
           ^^^^^^^^^^^^^^^^^^^^^^^^^^^^^^^^^^^^^^^^^^^^^^^^^^^^^^^^^^^^
  File "/home/airflow/.local/lib/python3.12/site-packages/airflow/models/baseoperator.py", line 400, in wrapper
    return func(self, *args, **kwargs)
           ^^^^^^^^^^^^^^^^^^^^^^^^^^^
  File "/home/airflow/.local/lib/python3.12/site-packages/airflow/operators/python.py", line 235, in execute
    return_value = self.execute_callable()
                   ^^^^^^^^^^^^^^^^^^^^^^^
  File "/home/airflow/.local/lib/python3.12/site-packages/airflow/operators/python.py", line 252, in execute_callable
    return self.python_callable(*self.op_args, **self.op_kwargs)
           ^^^^^^^^^^^^^^^^^^^^^^^^^^^^^^^^^^^^^^^^^^^^^^^^^^^^^
  File "/opt/airflow/dags/ETLProject/main.py", line 191, in check_folder_new
    with open(processed_file_list, 'a') as f:
         ^^^^^^^^^^^^^^^^^^^^^^^^^^^^^^
FileNotFoundError: [Errno 2] No such file or directory: 'dag/processed_list.txt'
[2024-10-09T10:17:25.739+0000] {taskinstance.py:1206} INFO - Marking task as UP_FOR_RETRY. dag_id=dag_ETL_JsonData, task_id=check_folder, run_id=manual__2024-10-09T10:07:22.471106+00:00, execution_date=20241009T100722, start_date=20241009T101725, end_date=20241009T101725
[2024-10-09T10:17:25.754+0000] {standard_task_runner.py:110} ERROR - Failed to execute job 808 for task check_folder ([Errno 2] No such file or directory: 'dag/processed_list.txt'; 858)
[2024-10-09T10:17:25.794+0000] {local_task_job_runner.py:240} INFO - Task exited with return code 1
[2024-10-09T10:17:25.814+0000] {taskinstance.py:3498} INFO - 0 downstream tasks scheduled from follow-on schedule check
[2024-10-09T10:17:25.817+0000] {local_task_job_runner.py:222} INFO - ::endgroup::
