[2024-10-03T09:31:33.287+0000] {local_task_job_runner.py:120} INFO - ::group::Pre task execution logs
[2024-10-03T09:31:33.318+0000] {taskinstance.py:2076} INFO - Dependencies all met for dep_context=non-requeueable deps ti=<TaskInstance: dag_ETL_JsonData.test manual__2024-10-03T09:26:31.029578+00:00 [queued]>
[2024-10-03T09:31:33.328+0000] {taskinstance.py:2076} INFO - Dependencies all met for dep_context=requeueable deps ti=<TaskInstance: dag_ETL_JsonData.test manual__2024-10-03T09:26:31.029578+00:00 [queued]>
[2024-10-03T09:31:33.329+0000] {taskinstance.py:2306} INFO - Starting attempt 2 of 6
[2024-10-03T09:31:33.344+0000] {taskinstance.py:2330} INFO - Executing <Task(PythonOperator): test> on 2024-10-03 09:26:31.029578+00:00
[2024-10-03T09:31:33.355+0000] {logging_mixin.py:188} WARNING - /home/***/.local/lib/python3.12/site-packages/***/task/task_runner/standard_task_runner.py:61 DeprecationWarning: This process (pid=579) is multi-threaded, use of fork() may lead to deadlocks in the child.
[2024-10-03T09:31:33.353+0000] {standard_task_runner.py:90} INFO - Running: ['***', 'tasks', 'run', 'dag_ETL_JsonData', 'test', 'manual__2024-10-03T09:26:31.029578+00:00', '--job-id', '139', '--raw', '--subdir', 'DAGS_FOLDER/ETLProject/main.py', '--cfg-path', '/tmp/tmp9cexqo6g']
[2024-10-03T09:31:33.356+0000] {standard_task_runner.py:91} INFO - Job 139: Subtask test
[2024-10-03T09:31:33.356+0000] {standard_task_runner.py:63} INFO - Started process 584 to run task
[2024-10-03T09:31:33.407+0000] {task_command.py:426} INFO - Running <TaskInstance: dag_ETL_JsonData.test manual__2024-10-03T09:26:31.029578+00:00 [running]> on host 233067a084ce
[2024-10-03T09:31:33.502+0000] {taskinstance.py:2648} INFO - Exporting env vars: AIRFLOW_CTX_DAG_OWNER='admin' AIRFLOW_CTX_DAG_ID='dag_ETL_JsonData' AIRFLOW_CTX_TASK_ID='test' AIRFLOW_CTX_EXECUTION_DATE='2024-10-03T09:26:31.029578+00:00' AIRFLOW_CTX_TRY_NUMBER='2' AIRFLOW_CTX_DAG_RUN_ID='manual__2024-10-03T09:26:31.029578+00:00'
[2024-10-03T09:31:33.503+0000] {taskinstance.py:430} INFO - ::endgroup::
[2024-10-03T09:31:33.514+0000] {taskinstance.py:441} INFO - ::group::Post task execution logs
[2024-10-03T09:31:33.515+0000] {taskinstance.py:2905} ERROR - Task failed with exception
Traceback (most recent call last):
  File "/home/airflow/.local/lib/python3.12/site-packages/airflow/models/taskinstance.py", line 465, in _execute_task
    result = _execute_callable(context=context, **execute_callable_kwargs)
             ^^^^^^^^^^^^^^^^^^^^^^^^^^^^^^^^^^^^^^^^^^^^^^^^^^^^^^^^^^^^^
  File "/home/airflow/.local/lib/python3.12/site-packages/airflow/models/taskinstance.py", line 432, in _execute_callable
    return execute_callable(context=context, **execute_callable_kwargs)
           ^^^^^^^^^^^^^^^^^^^^^^^^^^^^^^^^^^^^^^^^^^^^^^^^^^^^^^^^^^^^
  File "/home/airflow/.local/lib/python3.12/site-packages/airflow/models/baseoperator.py", line 400, in wrapper
    return func(self, *args, **kwargs)
           ^^^^^^^^^^^^^^^^^^^^^^^^^^^
  File "/home/airflow/.local/lib/python3.12/site-packages/airflow/operators/python.py", line 235, in execute
    return_value = self.execute_callable()
                   ^^^^^^^^^^^^^^^^^^^^^^^
  File "/home/airflow/.local/lib/python3.12/site-packages/airflow/operators/python.py", line 252, in execute_callable
    return self.python_callable(*self.op_args, **self.op_kwargs)
           ^^^^^^^^^^^^^^^^^^^^^^^^^^^^^^^^^^^^^^^^^^^^^^^^^^^^^
  File "/opt/airflow/dags/ETLProject/main.py", line 136, in test1
    df = pl.read_json('/otp/airflow/data/og_item_impression.20240830_2030_3.json')
         ^^^^^^^^^^^^^^^^^^^^^^^^^^^^^^^^^^^^^^^^^^^^^^^^^^^^^^^^^^^^^^^^^^^^^^^^^
  File "/home/airflow/.local/lib/python3.12/site-packages/polars/io/json/read.py", line 96, in read_json
    pydf = PyDataFrame.read_json(
           ^^^^^^^^^^^^^^^^^^^^^^
FileNotFoundError: No such file or directory (os error 2): /otp/***/data/og_item_impression.20240830_2030_3.json
[2024-10-03T09:31:33.534+0000] {taskinstance.py:1206} INFO - Marking task as UP_FOR_RETRY. dag_id=dag_ETL_JsonData, task_id=test, run_id=manual__2024-10-03T09:26:31.029578+00:00, execution_date=20241003T092631, start_date=20241003T093133, end_date=20241003T093133
[2024-10-03T09:31:33.548+0000] {standard_task_runner.py:110} ERROR - Failed to execute job 139 for task test (No such file or directory (os error 2): /otp/***/data/og_item_impression.20240830_2030_3.json; 584)
[2024-10-03T09:31:33.569+0000] {local_task_job_runner.py:240} INFO - Task exited with return code 1
[2024-10-03T09:31:33.587+0000] {taskinstance.py:3498} INFO - 0 downstream tasks scheduled from follow-on schedule check
[2024-10-03T09:31:33.590+0000] {local_task_job_runner.py:222} INFO - ::endgroup::
