[2024-10-09T10:23:41.501+0000] {local_task_job_runner.py:120} INFO - ::group::Pre task execution logs
[2024-10-09T10:23:41.539+0000] {taskinstance.py:2076} INFO - Dependencies all met for dep_context=non-requeueable deps ti=<TaskInstance: dag_ETL_JsonData.check_folder manual__2024-10-09T10:23:40.345430+00:00 [queued]>
[2024-10-09T10:23:41.551+0000] {taskinstance.py:2076} INFO - Dependencies all met for dep_context=requeueable deps ti=<TaskInstance: dag_ETL_JsonData.check_folder manual__2024-10-09T10:23:40.345430+00:00 [queued]>
[2024-10-09T10:23:41.552+0000] {taskinstance.py:2306} INFO - Starting attempt 1 of 6
[2024-10-09T10:23:41.572+0000] {taskinstance.py:2330} INFO - Executing <Task(PythonOperator): check_folder> on 2024-10-09 10:23:40.345430+00:00
[2024-10-09T10:23:41.590+0000] {logging_mixin.py:188} WARNING - /home/***/.local/lib/python3.12/site-packages/***/task/task_runner/standard_task_runner.py:61 DeprecationWarning: This process (pid=1224) is multi-threaded, use of fork() may lead to deadlocks in the child.
[2024-10-09T10:23:41.586+0000] {standard_task_runner.py:90} INFO - Running: ['***', 'tasks', 'run', 'dag_ETL_JsonData', 'check_folder', 'manual__2024-10-09T10:23:40.345430+00:00', '--job-id', '818', '--raw', '--subdir', 'DAGS_FOLDER/ETLProject/main.py', '--cfg-path', '/tmp/tmpyx0tliho']
[2024-10-09T10:23:41.591+0000] {standard_task_runner.py:63} INFO - Started process 1235 to run task
[2024-10-09T10:23:41.592+0000] {standard_task_runner.py:91} INFO - Job 818: Subtask check_folder
[2024-10-09T10:23:41.691+0000] {task_command.py:426} INFO - Running <TaskInstance: dag_ETL_JsonData.check_folder manual__2024-10-09T10:23:40.345430+00:00 [running]> on host ecb02e117702
[2024-10-09T10:23:41.808+0000] {taskinstance.py:2648} INFO - Exporting env vars: AIRFLOW_CTX_DAG_OWNER='admin' AIRFLOW_CTX_DAG_ID='dag_ETL_JsonData' AIRFLOW_CTX_TASK_ID='check_folder' AIRFLOW_CTX_EXECUTION_DATE='2024-10-09T10:23:40.345430+00:00' AIRFLOW_CTX_TRY_NUMBER='1' AIRFLOW_CTX_DAG_RUN_ID='manual__2024-10-09T10:23:40.345430+00:00'
[2024-10-09T10:23:41.809+0000] {taskinstance.py:430} INFO - ::endgroup::
[2024-10-09T10:23:41.857+0000] {taskinstance.py:441} INFO - ::group::Post task execution logs
[2024-10-09T10:23:41.858+0000] {taskinstance.py:2905} ERROR - Task failed with exception
Traceback (most recent call last):
  File "/home/airflow/.local/lib/python3.12/site-packages/airflow/models/taskinstance.py", line 465, in _execute_task
    result = _execute_callable(context=context, **execute_callable_kwargs)
             ^^^^^^^^^^^^^^^^^^^^^^^^^^^^^^^^^^^^^^^^^^^^^^^^^^^^^^^^^^^^^
  File "/home/airflow/.local/lib/python3.12/site-packages/airflow/models/taskinstance.py", line 432, in _execute_callable
    return execute_callable(context=context, **execute_callable_kwargs)
           ^^^^^^^^^^^^^^^^^^^^^^^^^^^^^^^^^^^^^^^^^^^^^^^^^^^^^^^^^^^^
  File "/home/airflow/.local/lib/python3.12/site-packages/airflow/models/baseoperator.py", line 400, in wrapper
    return func(self, *args, **kwargs)
           ^^^^^^^^^^^^^^^^^^^^^^^^^^^
  File "/home/airflow/.local/lib/python3.12/site-packages/airflow/operators/python.py", line 235, in execute
    return_value = self.execute_callable()
                   ^^^^^^^^^^^^^^^^^^^^^^^
  File "/home/airflow/.local/lib/python3.12/site-packages/airflow/operators/python.py", line 252, in execute_callable
    return self.python_callable(*self.op_args, **self.op_kwargs)
           ^^^^^^^^^^^^^^^^^^^^^^^^^^^^^^^^^^^^^^^^^^^^^^^^^^^^^
  File "/opt/airflow/dags/ETLProject/main.py", line 191, in check_folder_new
    with open(processed_file_list, 'a') as f:
         ^^^^^^^^^^^^^^^^^^^^^^^^^^^^^^
FileNotFoundError: [Errno 2] No such file or directory: '/dag/processed_list.txt'
[2024-10-09T10:23:41.876+0000] {taskinstance.py:1206} INFO - Marking task as UP_FOR_RETRY. dag_id=dag_ETL_JsonData, task_id=check_folder, run_id=manual__2024-10-09T10:23:40.345430+00:00, execution_date=20241009T102340, start_date=20241009T102341, end_date=20241009T102341
[2024-10-09T10:23:41.896+0000] {standard_task_runner.py:110} ERROR - Failed to execute job 818 for task check_folder ([Errno 2] No such file or directory: '/dag/processed_list.txt'; 1235)
[2024-10-09T10:23:41.943+0000] {local_task_job_runner.py:240} INFO - Task exited with return code 1
[2024-10-09T10:23:41.961+0000] {taskinstance.py:3498} INFO - 0 downstream tasks scheduled from follow-on schedule check
[2024-10-09T10:23:41.965+0000] {local_task_job_runner.py:222} INFO - ::endgroup::
