[2024-10-04T02:58:28.726+0000] {local_task_job_runner.py:120} INFO - ::group::Pre task execution logs
[2024-10-04T02:58:28.814+0000] {taskinstance.py:2076} INFO - Dependencies all met for dep_context=non-requeueable deps ti=<TaskInstance: dag_ETL_JsonData.test manual__2024-10-04T02:43:17.793029+00:00 [queued]>
[2024-10-04T02:58:28.835+0000] {taskinstance.py:2076} INFO - Dependencies all met for dep_context=requeueable deps ti=<TaskInstance: dag_ETL_JsonData.test manual__2024-10-04T02:43:17.793029+00:00 [queued]>
[2024-10-04T02:58:28.837+0000] {taskinstance.py:2306} INFO - Starting attempt 4 of 6
[2024-10-04T02:58:28.870+0000] {taskinstance.py:2330} INFO - Executing <Task(PythonOperator): test> on 2024-10-04 02:43:17.793029+00:00
[2024-10-04T02:58:28.885+0000] {logging_mixin.py:188} WARNING - /home/***/.local/lib/python3.12/site-packages/***/task/task_runner/standard_task_runner.py:61 DeprecationWarning: This process (pid=608) is multi-threaded, use of fork() may lead to deadlocks in the child.
[2024-10-04T02:58:28.888+0000] {standard_task_runner.py:63} INFO - Started process 615 to run task
[2024-10-04T02:58:28.888+0000] {standard_task_runner.py:90} INFO - Running: ['***', 'tasks', 'run', 'dag_ETL_JsonData', 'test', 'manual__2024-10-04T02:43:17.793029+00:00', '--job-id', '293', '--raw', '--subdir', 'DAGS_FOLDER/ETLProject/main.py', '--cfg-path', '/tmp/tmp9bmgjxvc']
[2024-10-04T02:58:28.892+0000] {standard_task_runner.py:91} INFO - Job 293: Subtask test
[2024-10-04T02:58:29.056+0000] {task_command.py:426} INFO - Running <TaskInstance: dag_ETL_JsonData.test manual__2024-10-04T02:43:17.793029+00:00 [running]> on host ecb02e117702
[2024-10-04T02:58:29.358+0000] {taskinstance.py:2648} INFO - Exporting env vars: AIRFLOW_CTX_DAG_OWNER='admin' AIRFLOW_CTX_DAG_ID='dag_ETL_JsonData' AIRFLOW_CTX_TASK_ID='test' AIRFLOW_CTX_EXECUTION_DATE='2024-10-04T02:43:17.793029+00:00' AIRFLOW_CTX_TRY_NUMBER='4' AIRFLOW_CTX_DAG_RUN_ID='manual__2024-10-04T02:43:17.793029+00:00'
[2024-10-04T02:58:29.361+0000] {taskinstance.py:430} INFO - ::endgroup::
[2024-10-04T02:58:29.385+0000] {taskinstance.py:441} INFO - ::group::Post task execution logs
[2024-10-04T02:58:29.389+0000] {taskinstance.py:2905} ERROR - Task failed with exception
Traceback (most recent call last):
  File "/home/airflow/.local/lib/python3.12/site-packages/airflow/models/taskinstance.py", line 465, in _execute_task
    result = _execute_callable(context=context, **execute_callable_kwargs)
             ^^^^^^^^^^^^^^^^^^^^^^^^^^^^^^^^^^^^^^^^^^^^^^^^^^^^^^^^^^^^^
  File "/home/airflow/.local/lib/python3.12/site-packages/airflow/models/taskinstance.py", line 432, in _execute_callable
    return execute_callable(context=context, **execute_callable_kwargs)
           ^^^^^^^^^^^^^^^^^^^^^^^^^^^^^^^^^^^^^^^^^^^^^^^^^^^^^^^^^^^^
  File "/home/airflow/.local/lib/python3.12/site-packages/airflow/models/baseoperator.py", line 400, in wrapper
    return func(self, *args, **kwargs)
           ^^^^^^^^^^^^^^^^^^^^^^^^^^^
  File "/home/airflow/.local/lib/python3.12/site-packages/airflow/operators/python.py", line 235, in execute
    return_value = self.execute_callable()
                   ^^^^^^^^^^^^^^^^^^^^^^^
  File "/home/airflow/.local/lib/python3.12/site-packages/airflow/operators/python.py", line 252, in execute_callable
    return self.python_callable(*self.op_args, **self.op_kwargs)
           ^^^^^^^^^^^^^^^^^^^^^^^^^^^^^^^^^^^^^^^^^^^^^^^^^^^^^
  File "/opt/airflow/dags/ETLProject/main.py", line 136, in test1
    df = pl.read_json('/data/og_item_impression.20240830_2030_3.json/og_item_impression.20240830_2030_3.json')
         ^^^^^^^^^^^^^^^^^^^^^^^^^^^^^^^^^^^^^^^^^^^^^^^^^^^^^^^^^^^^^^^^^^^^^^^^^^^^^^^^^^^^^^^^^^^^^^^^^^^^^
  File "/home/airflow/.local/lib/python3.12/site-packages/polars/io/json/read.py", line 96, in read_json
    pydf = PyDataFrame.read_json(
           ^^^^^^^^^^^^^^^^^^^^^^
FileNotFoundError: No such file or directory (os error 2): /data/og_item_impression.20240830_2030_3.json/og_item_impression.20240830_2030_3.json
[2024-10-04T02:58:29.442+0000] {taskinstance.py:1206} INFO - Marking task as UP_FOR_RETRY. dag_id=dag_ETL_JsonData, task_id=test, run_id=manual__2024-10-04T02:43:17.793029+00:00, execution_date=20241004T024317, start_date=20241004T025828, end_date=20241004T025829
[2024-10-04T02:58:29.473+0000] {standard_task_runner.py:110} ERROR - Failed to execute job 293 for task test (No such file or directory (os error 2): /data/og_item_impression.20240830_2030_3.json/og_item_impression.20240830_2030_3.json; 615)
[2024-10-04T02:58:29.506+0000] {local_task_job_runner.py:240} INFO - Task exited with return code 1
[2024-10-04T02:58:29.538+0000] {taskinstance.py:3498} INFO - 0 downstream tasks scheduled from follow-on schedule check
[2024-10-04T02:58:29.544+0000] {local_task_job_runner.py:222} INFO - ::endgroup::
