[2024-10-04T03:46:18.394+0000] {local_task_job_runner.py:120} INFO - ::group::Pre task execution logs
[2024-10-04T03:46:18.539+0000] {taskinstance.py:2076} INFO - Dependencies all met for dep_context=non-requeueable deps ti=<TaskInstance: dag_ETL_JsonData.test manual__2024-10-04T02:43:17.793029+00:00 [queued]>
[2024-10-04T03:46:18.561+0000] {taskinstance.py:2076} INFO - Dependencies all met for dep_context=requeueable deps ti=<TaskInstance: dag_ETL_JsonData.test manual__2024-10-04T02:43:17.793029+00:00 [queued]>
[2024-10-04T03:46:18.565+0000] {taskinstance.py:2306} INFO - Starting attempt 6 of 6
[2024-10-04T03:46:18.716+0000] {taskinstance.py:2330} INFO - Executing <Task(PythonOperator): test> on 2024-10-04 02:43:17.793029+00:00
[2024-10-04T03:46:18.748+0000] {standard_task_runner.py:90} INFO - Running: ['***', 'tasks', 'run', 'dag_ETL_JsonData', 'test', 'manual__2024-10-04T02:43:17.793029+00:00', '--job-id', '371', '--raw', '--subdir', 'DAGS_FOLDER/ETLProject/main.py', '--cfg-path', '/tmp/tmpzohcocyq']
[2024-10-04T03:46:18.753+0000] {logging_mixin.py:188} WARNING - /home/***/.local/lib/python3.12/site-packages/***/task/task_runner/standard_task_runner.py:61 DeprecationWarning: This process (pid=3403) is multi-threaded, use of fork() may lead to deadlocks in the child.
[2024-10-04T03:46:18.761+0000] {standard_task_runner.py:63} INFO - Started process 3439 to run task
[2024-10-04T03:46:18.778+0000] {standard_task_runner.py:91} INFO - Job 371: Subtask test
[2024-10-04T03:46:19.088+0000] {task_command.py:426} INFO - Running <TaskInstance: dag_ETL_JsonData.test manual__2024-10-04T02:43:17.793029+00:00 [running]> on host ecb02e117702
[2024-10-04T03:46:19.393+0000] {taskinstance.py:2648} INFO - Exporting env vars: AIRFLOW_CTX_DAG_OWNER='admin' AIRFLOW_CTX_DAG_ID='dag_ETL_JsonData' AIRFLOW_CTX_TASK_ID='test' AIRFLOW_CTX_EXECUTION_DATE='2024-10-04T02:43:17.793029+00:00' AIRFLOW_CTX_TRY_NUMBER='6' AIRFLOW_CTX_DAG_RUN_ID='manual__2024-10-04T02:43:17.793029+00:00'
[2024-10-04T03:46:19.426+0000] {taskinstance.py:430} INFO - ::endgroup::
[2024-10-04T03:46:19.460+0000] {taskinstance.py:441} INFO - ::group::Post task execution logs
[2024-10-04T03:46:19.462+0000] {taskinstance.py:2905} ERROR - Task failed with exception
Traceback (most recent call last):
  File "/home/airflow/.local/lib/python3.12/site-packages/airflow/models/taskinstance.py", line 465, in _execute_task
    result = _execute_callable(context=context, **execute_callable_kwargs)
             ^^^^^^^^^^^^^^^^^^^^^^^^^^^^^^^^^^^^^^^^^^^^^^^^^^^^^^^^^^^^^
  File "/home/airflow/.local/lib/python3.12/site-packages/airflow/models/taskinstance.py", line 432, in _execute_callable
    return execute_callable(context=context, **execute_callable_kwargs)
           ^^^^^^^^^^^^^^^^^^^^^^^^^^^^^^^^^^^^^^^^^^^^^^^^^^^^^^^^^^^^
  File "/home/airflow/.local/lib/python3.12/site-packages/airflow/models/baseoperator.py", line 400, in wrapper
    return func(self, *args, **kwargs)
           ^^^^^^^^^^^^^^^^^^^^^^^^^^^
  File "/home/airflow/.local/lib/python3.12/site-packages/airflow/operators/python.py", line 235, in execute
    return_value = self.execute_callable()
                   ^^^^^^^^^^^^^^^^^^^^^^^
  File "/home/airflow/.local/lib/python3.12/site-packages/airflow/operators/python.py", line 252, in execute_callable
    return self.python_callable(*self.op_args, **self.op_kwargs)
           ^^^^^^^^^^^^^^^^^^^^^^^^^^^^^^^^^^^^^^^^^^^^^^^^^^^^^
  File "/opt/airflow/dags/ETLProject/main.py", line 136, in test1
    df = pl.read_json('/data/og_item_impression.20240830_2030_3.json/og_item_impression.20240830_2030_3.json')
         ^^^^^^^^^^^^^^^^^^^^^^^^^^^^^^^^^^^^^^^^^^^^^^^^^^^^^^^^^^^^^^^^^^^^^^^^^^^^^^^^^^^^^^^^^^^^^^^^^^^^^
  File "/home/airflow/.local/lib/python3.12/site-packages/polars/io/json/read.py", line 96, in read_json
    pydf = PyDataFrame.read_json(
           ^^^^^^^^^^^^^^^^^^^^^^
FileNotFoundError: No such file or directory (os error 2): /data/og_item_impression.20240830_2030_3.json/og_item_impression.20240830_2030_3.json
[2024-10-04T03:46:19.524+0000] {taskinstance.py:1206} INFO - Marking task as FAILED. dag_id=dag_ETL_JsonData, task_id=test, run_id=manual__2024-10-04T02:43:17.793029+00:00, execution_date=20241004T024317, start_date=20241004T034618, end_date=20241004T034619
[2024-10-04T03:46:19.559+0000] {standard_task_runner.py:110} ERROR - Failed to execute job 371 for task test (No such file or directory (os error 2): /data/og_item_impression.20240830_2030_3.json/og_item_impression.20240830_2030_3.json; 3439)
[2024-10-04T03:46:19.626+0000] {local_task_job_runner.py:240} INFO - Task exited with return code 1
[2024-10-04T03:46:19.653+0000] {local_task_job_runner.py:222} INFO - ::endgroup::
