[2024-10-04T02:43:23.399+0000] {local_task_job_runner.py:120} INFO - ::group::Pre task execution logs
[2024-10-04T02:43:23.629+0000] {taskinstance.py:2076} INFO - Dependencies all met for dep_context=non-requeueable deps ti=<TaskInstance: dag_ETL_JsonData.test scheduled__2024-10-03T13:01:00+00:00 [queued]>
[2024-10-04T02:43:23.737+0000] {taskinstance.py:2076} INFO - Dependencies all met for dep_context=requeueable deps ti=<TaskInstance: dag_ETL_JsonData.test scheduled__2024-10-03T13:01:00+00:00 [queued]>
[2024-10-04T02:43:23.738+0000] {taskinstance.py:2306} INFO - Starting attempt 1 of 6
[2024-10-04T02:43:23.900+0000] {taskinstance.py:2330} INFO - Executing <Task(PythonOperator): test> on 2024-10-03 13:01:00+00:00
[2024-10-04T02:43:23.988+0000] {standard_task_runner.py:90} INFO - Running: ['***', 'tasks', 'run', 'dag_ETL_JsonData', 'test', 'scheduled__2024-10-03T13:01:00+00:00', '--job-id', '202', '--raw', '--subdir', 'DAGS_FOLDER/ETLProject/main.py', '--cfg-path', '/tmp/tmppmp6976h']
[2024-10-04T02:43:24.017+0000] {logging_mixin.py:188} WARNING - /home/***/.local/lib/python3.12/site-packages/***/task/task_runner/standard_task_runner.py:61 DeprecationWarning: This process (pid=367) is multi-threaded, use of fork() may lead to deadlocks in the child.
[2024-10-04T02:43:24.045+0000] {standard_task_runner.py:91} INFO - Job 202: Subtask test
[2024-10-04T02:43:24.061+0000] {standard_task_runner.py:63} INFO - Started process 389 to run task
[2024-10-04T02:43:24.547+0000] {task_command.py:426} INFO - Running <TaskInstance: dag_ETL_JsonData.test scheduled__2024-10-03T13:01:00+00:00 [running]> on host 233067a084ce
[2024-10-04T02:43:24.896+0000] {taskinstance.py:2648} INFO - Exporting env vars: AIRFLOW_CTX_DAG_OWNER='admin' AIRFLOW_CTX_DAG_ID='dag_ETL_JsonData' AIRFLOW_CTX_TASK_ID='test' AIRFLOW_CTX_EXECUTION_DATE='2024-10-03T13:01:00+00:00' AIRFLOW_CTX_TRY_NUMBER='1' AIRFLOW_CTX_DAG_RUN_ID='scheduled__2024-10-03T13:01:00+00:00'
[2024-10-04T02:43:24.905+0000] {taskinstance.py:430} INFO - ::endgroup::
[2024-10-04T02:43:24.958+0000] {taskinstance.py:441} INFO - ::group::Post task execution logs
[2024-10-04T02:43:24.961+0000] {taskinstance.py:2905} ERROR - Task failed with exception
Traceback (most recent call last):
  File "/home/airflow/.local/lib/python3.12/site-packages/airflow/models/taskinstance.py", line 465, in _execute_task
    result = _execute_callable(context=context, **execute_callable_kwargs)
             ^^^^^^^^^^^^^^^^^^^^^^^^^^^^^^^^^^^^^^^^^^^^^^^^^^^^^^^^^^^^^
  File "/home/airflow/.local/lib/python3.12/site-packages/airflow/models/taskinstance.py", line 432, in _execute_callable
    return execute_callable(context=context, **execute_callable_kwargs)
           ^^^^^^^^^^^^^^^^^^^^^^^^^^^^^^^^^^^^^^^^^^^^^^^^^^^^^^^^^^^^
  File "/home/airflow/.local/lib/python3.12/site-packages/airflow/models/baseoperator.py", line 400, in wrapper
    return func(self, *args, **kwargs)
           ^^^^^^^^^^^^^^^^^^^^^^^^^^^
  File "/home/airflow/.local/lib/python3.12/site-packages/airflow/operators/python.py", line 235, in execute
    return_value = self.execute_callable()
                   ^^^^^^^^^^^^^^^^^^^^^^^
  File "/home/airflow/.local/lib/python3.12/site-packages/airflow/operators/python.py", line 252, in execute_callable
    return self.python_callable(*self.op_args, **self.op_kwargs)
           ^^^^^^^^^^^^^^^^^^^^^^^^^^^^^^^^^^^^^^^^^^^^^^^^^^^^^
  File "/opt/airflow/dags/ETLProject/main.py", line 136, in test1
    df = pl.read_json('/data/og_item_impression.20240830_2030_3.json/og_item_impression.20240830_2030_3.json')
         ^^^^^^^^^^^^^^^^^^^^^^^^^^^^^^^^^^^^^^^^^^^^^^^^^^^^^^^^^^^^^^^^^^^^^^^^^^^^^^^^^^^^^^^^^^^^^^^^^^^^^
  File "/home/airflow/.local/lib/python3.12/site-packages/polars/io/json/read.py", line 96, in read_json
    pydf = PyDataFrame.read_json(
           ^^^^^^^^^^^^^^^^^^^^^^
FileNotFoundError: No such file or directory (os error 2): /data/og_item_impression.20240830_2030_3.json/og_item_impression.20240830_2030_3.json
[2024-10-04T02:43:25.079+0000] {taskinstance.py:1206} INFO - Marking task as UP_FOR_RETRY. dag_id=dag_ETL_JsonData, task_id=test, run_id=scheduled__2024-10-03T13:01:00+00:00, execution_date=20241003T130100, start_date=20241004T024323, end_date=20241004T024325
[2024-10-04T02:43:25.151+0000] {standard_task_runner.py:110} ERROR - Failed to execute job 202 for task test (No such file or directory (os error 2): /data/og_item_impression.20240830_2030_3.json/og_item_impression.20240830_2030_3.json; 389)
[2024-10-04T02:43:25.218+0000] {local_task_job_runner.py:240} INFO - Task exited with return code 1
[2024-10-04T02:43:25.253+0000] {local_task_job_runner.py:222} INFO - ::endgroup::
